Workbook

Sheet Оқы мені
A1: ГИПОТЕЗА, ТОЛТЫРЫЛМАҒАН БОЛЖАМДАР
A2: Бұл файл - ШАБЛОН. Ішінде нақты баға, клиент, табыс, нарық көлемі не өсім жоқ: олар әлі белгісіз (QazaqCode пилотқа дейінгі сатыда, төленген клиент жоқ).
A3: Нәтижелер (кіріс, P&L, runway, LTV/CAC) тек сіз енгізген гипотезаларға тәуелді. Болжамдарды толтырмай тұрып барлығы 0 немесе "—" болады: бұл дұрыс.
A5: Қалай қолдану
A6: 1. 'Болжамдар' парағында ЖЕЛТОҚ ұяшықтарды (көк қаріп) толтырыңыз: үш сценарий үшін бөлек (консервативті / базалық / оптимистік).
A7: 2. Жоғарғы ұяшықтан белсенді сценарийді таңдаңыз. Шығын, P&L, Cash, Бірлік экономикасы таңдалған сценарийді көрсетеді; 'Кіріс' парағында үш сценарий да бөлек есептеледі.
A8: 3. Баға мен шығынды ПИЛОТТАН кейінгі нақты деректермен ауыстырыңыз. Дереккөзсіз сан енгізбеңіз немесе енгізсеңіз, дереккөзін ескертуге жазыңыз.
A10: Түс кодтары
A11: Көк қаріп + жолақты сары фон = КІРІС ұяшығы (гипотеза, пайдаланушы енгізеді).
A12: Қара қаріп = ФОРМУЛА (қолмен өзгертпеңіз).
A14: Шектеулер
A15: - Модель жеңілдетілген: мектеп = бір жылдық лицензия, төлем ай сайын бөлінген (MRR = мектеп x оқушы x жылдық баға / 12).
... A18: - Пилот сатысында: [docs/INVESTOR.md] ішіндегі бизнес-модель - гипотеза.

Sheet Болжамдар
A1: Болжамдар (ГИПОТЕЗА: толтырылмаған)
A2: Белсенді сценарий: | B2: Базалық | C2: индекс: | D2: =IFERROR(MATCH($B$2,$C$4:$E$4,0),2)
A3: Барлық желтоқ ұяшық - ГИПОТЕЗА. Бос = әлі белгісіз (есептеуде 0). Дереккөзін G бағанына жазыңыз.
A4: Параметр | B4: Бірлік | C4: Консервативті | D4: Базалық | E4: Оптимистік | F4: Белсенді | G4: Ескерту
A5: Баға және клиенттер
A6: Баға: 1 оқушы / жыл | B6: ₸ | F6: =INDEX(C6:E6,1,$D$2) | G6: ГИПОТЕЗА: толтырыңыз (0 / бос)
A7: Оқушы саны / мектеп | B7: оқушы | F7: =INDEX(C7:E7,1,$D$2) | G7: ГИПОТЕЗА: толтырыңыз (0 / бос)
A8: Бастапқы төлеуші мектеп саны (1-айда) | B8: мектеп | F8: =INDEX(C8:E8,1,$D$2) | G8: ГИПОТЕЗА: толтырыңыз (0 / бос)
A9: Воронка (сату)
A10: Жаңа лид (мектеп сұрауы) / ай | B10: лид | F10: =INDEX(C10:E10,1,$D$2) | G10: ГИПОТЕЗА: толтырыңыз (0 / бос)
A11: Лид -> пилот конверсиясы | B11: % | F11: =INDEX(C11:E11,1,$D$2) | G11: ГИПОТЕЗА: толтырыңыз (0 / бос)
A12: Пилот -> төлеуші конверсиясы | B12: % | F12: =INDEX(C12:E12,1,$D$2) | G12: ГИПОТЕЗА: толтырыңыз (0 / бос)
A13: Пилоттан төлеушіге дейінгі кідіріс | B13: ай | F13: =INDEX(C13:E13,1,$D$2) | G13: ГИПОТЕЗА: толтырыңыз (0 / бос)
A14: Айлық churn (төлеуші мектептер) | B14: %/ай | F14: =INDEX(C14:E14,1,$D$2) | G14: ГИПОТЕЗА: толтырыңыз (0 / бос)
A15: Ауыспалы шығындар
A16: Хостинг шығыны / мектеп / ай | B16: ₸ | F16: =INDEX(C16:E16,1,$D$2) | G16: ГИПОТЕЗА: толтырыңыз (0 / бос)
A17: Қолдау сағаты / мектеп / ай | B17: сағат | F17: =INDEX(C17:E17,1,$D$2) | G17: ГИПОТЕЗА: толтырыңыз (0 / бос)
A18: Қолдау сағатының құны | B18: ₸/сағат | F18: =INDEX(C18:E18,1,$D$2) | G18: ГИПОТЕЗА: толтырыңыз (0 / бос)
A19: Төлем комиссиясы және салық (кірістен) | B19: % | F19: =INDEX(C19:E19,1,$D$2) | G19: ГИПОТЕЗА: толтырыңыз (0 / бос)
A20: Тұрақты шығындар (ай сайын)
A21: Тұрақты хостинг / инфрақұрылым / ай | B21: ₸ | F21: =INDEX(C21:E21,1,$D$2) | G21: ГИПОТЕЗА: толтырыңыз (0 / бос)
A22: Қызметкер саны (жалақы алатын) | B22: адам | F22: =INDEX(C22:E22,1,$D$2) | G22: ГИПОТЕЗА: толтырыңыз (0 / бос)
A23: Орташа жалақы / адам / ай | B23: ₸ | F23: =INDEX(C23:E23,1,$D$2) | G23: ГИПОТЕЗА: толтырыңыз (0 / бос)
A24: Заңгер / ай | B24: ₸ | F24: =INDEX(C24:E24,1,$D$2) | G24: ГИПОТЕЗА: толтырыңыз (0 / бос)
A25: Маркетинг және сату / ай | B25: ₸ | F25: =INDEX(C25:E25,1,$D$2) | G25: ГИПОТЕЗА: толтырыңыз (0 / бос)
A26: Қаржы
A27: Бастапқы касса (0-ай) | B27: ₸ | F27: =INDEX(C27:E27,1,$D$2) | G27: ГИПОТЕЗА: толтырыңыз (0 / бос)

Sheet Кіріс
A1: Кіріс (36 ай): MRR / ARR
A2: ГИПОТЕЗА: барлық болжам 'Болжамдар' парағынан; толтырылмаса 0.
A4: Көрсеткіш | B4: Бірлік | C4: Жиыны / соңы | D4: 1 | E4: =D4+1 | F4: =E4+1 | G4: =F4+1 | H4: =G4+1 | I4: =H4+1 | J4: =I4+1 | K4: =J4+1 | L4: =K4+1 | ... AM4: =AL4+1
A5: БЕЛСЕНДІ сценарий (Болжамдар!B2 таңдауы)
A6: Жаңа лид | B6: мектеп | C6: =SUM(D6:AM6) | D6: =CHOOSE('Болжамдар'!$D$2,D18,D30,D42) | E6: =CHOOSE('Болжамдар'!$D$2,E18,E30,E42) | F6: =CHOOSE('Болжамдар'!$D$2,F18,F30,F42) | G6: =CHOOSE('Болжамдар'!$D$2,G18,G30,G42) | H6: =CHOOSE('Болжамдар'!$D$2,H18,H30,H42) | I6: =CHOOSE('Болжамдар'!$D$2,I18,I30,I42) | J6: =CHOOSE('Болжамдар'!$D$2,J18,J30,J42) | K6: =CHOOSE('Болжамдар'!$D$2,K18,K30,K42) | ... AM6: =CHOOSE('Болжамдар'!$D$2,AM18,AM30,AM42)
A7: Жаңа пилот | B7: мектеп | C7: =SUM(D7:AM7) | D7: =CHOOSE('Болжамдар'!$D$2,D19,D31,D43) | E7: =CHOOSE('Болжамдар'!$D$2,E19,E31,E43) | F7: =CHOOSE('Болжамдар'!$D$2,F19,F31,F43) | G7: =CHOOSE('Болжамдар'!$D$2,G19,G31,G43) | H7: =CHOOSE('Болжамдар'!$D$2,H19,H31,H43) | I7: =CHOOSE('Болжамдар'!$D$2,I19,I31,I43) | J7: =CHOOSE('Болжамдар'!$D$2,J19,J31,J43) | K7: =CHOOSE('Болжамдар'!$D$2,K19,K31,K43) | ... AM7: =CHOOSE('Болжамдар'!$D$2,AM19,AM31,AM43)
A8: Жаңа төлеуші мектеп | B8: мектеп | C8: =SUM(D8:AM8) | D8: =CHOOSE('Болжамдар'!$D$2,D20,D32,D44) | E8: =CHOOSE('Болжамдар'!$D$2,E20,E32,E44) | F8: =CHOOSE('Болжамдар'!$D$2,F20,F32,F44) | G8: =CHOOSE('Болжамдар'!$D$2,G20,G32,G44) | H8: =CHOOSE('Болжамдар'!$D$2,H20,H32,H44) | I8: =CHOOSE('Болжамдар'!$D$2,I20,I32,I44) | J8: =CHOOSE('Болжамдар'!$D$2,J20,J32,J44) | K8: =CHOOSE('Болжамдар'!$D$2,K20,K32,K44) | ... AM8: =CHOOSE('Болжамдар'!$D$2,AM20,AM32,AM44)
A9: Кеткен (churn) мектеп | B9: мектеп | C9: =SUM(D9:AM9) | D9: =CHOOSE('Болжамдар'!$D$2,D21,D33,D45) | E9: =CHOOSE('Болжамдар'!$D$2,E21,E33,E45) | F9: =CHOOSE('Болжамдар'!$D$2,F21,F33,F45) | G9: =CHOOSE('Болжамдар'!$D$2,G21,G33,G45) | H9: =CHOOSE('Болжамдар'!$D$2,H21,H33,H45) | I9: =CHOOSE('Болжамдар'!$D$2,I21,I33,I45) | J9: =CHOOSE('Болжамдар'!$D$2,J21,J33,J45) | K9: =CHOOSE('Болжамдар'!$D$2,K21,K33,K45) | ... AM9: =CHOOSE('Болжамдар'!$D$2,AM21,AM33,AM45)
A10: Белсенді төлеуші мектеп | B10: мектеп | C10: =AM10 | D10: =CHOOSE('Болжамдар'!$D$2,D22,D34,D46) | E10: =CHOOSE('Болжамдар'!$D$2,E22,E34,E46) | F10: =CHOOSE('Болжамдар'!$D$2,F22,F34,F46) | G10: =CHOOSE('Болжамдар'!$D$2,G22,G34,G46) | H10: =CHOOSE('Болжамдар'!$D$2,H22,H34,H46) | I10: =CHOOSE('Болжамдар'!$D$2,I22,I34,I46) | J10: =CHOOSE('Болжамдар'!$D$2,J22,J34,J46) | K10: =CHOOSE('Болжамдар'!$D$2,K22,K34,K46) | ... AM10: =CHOOSE('Болжамдар'!$D$2,AM22,AM34,AM46)
A11: Төлеуші оқушылар | B11: оқушы | C11: =AM11 | D11: =CHOOSE('Болжамдар'!$D$2,D23,D35,D47) | E11: =CHOOSE('Болжамдар'!$D$2,E23,E35,E47) | F11: =CHOOSE('Болжамдар'!$D$2,F23,F35,F47) | G11: =CHOOSE('Болжамдар'!$D$2,G23,G35,G47) | H11: =CHOOSE('Болжамдар'!$D$2,H23,H35,H47) | I11: =CHOOSE('Болжамдар'!$D$2,I23,I35,I47) | J11: =CHOOSE('Болжамдар'!$D$2,J23,J35,J47) | K11: =CHOOSE('Болжамдар'!$D$2,K23,K35,K47) | ... AM11: =CHOOSE('Болжамдар'!$D$2,AM23,AM35,AM47)
A12: MRR | B12: ₸/ай | C12: =AM12 | D12: =CHOOSE('Болжамдар'!$D$2,D24,D36,D48) | E12: =CHOOSE('Болжамдар'!$D$2,E24,E36,E48) | F12: =CHOOSE('Болжамдар'!$D$2,F24,F36,F48) | G12: =CHOOSE('Болжамдар'!$D$2,G24,G36,G48) | H12: =CHOOSE('Болжамдар'!$D$2,H24,H36,H48) | I12: =CHOOSE('Болжамдар'!$D$2,I24,I36,I48) | J12: =CHOOSE('Болжамдар'!$D$2,J24,J36,J48) | K12: =CHOOSE('Болжамдар'!$D$2,K24,K36,K48) | ... AM12: =CHOOSE('Болжамдар'!$D$2,AM24,AM36,AM48)
A13: ARR (= MRR x 12) | B13: ₸/жыл | C13: =AM13 | D13: =CHOOSE('Болжамдар'!$D$2,D25,D37,D49) | E13: =CHOOSE('Болжамдар'!$D$2,E25,E37,E49) | F13: =CHOOSE('Болжамдар'!$D$2,F25,F37,F49) | G13: =CHOOSE('Болжамдар'!$D$2,G25,G37,G49) | H13: =CHOOSE('Болжамдар'!$D$2,H25,H37,H49) | I13: =CHOOSE('Болжамдар'!$D$2,I25,I37,I49) | J13: =CHOOSE('Болжамдар'!$D$2,J25,J37,J49) | K13: =CHOOSE('Болжамдар'!$D$2,K25,K37,K49) | ... AM13: =CHOOSE('Болжамдар'!$D$2,AM25,AM37,AM49)
A14: Кіріс (ай) | B14: ₸ | C14: =SUM(D14:AM14) | D14: =CHOOSE('Болжамдар'!$D$2,D26,D38,D50) | E14: =CHOOSE('Болжамдар'!$D$2,E26,E38,E50) | F14: =CHOOSE('Болжамдар'!$D$2,F26,F38,F50) | G14: =CHOOSE('Болжамдар'!$D$2,G26,G38,G50) | H14: =CHOOSE('Болжамдар'!$D$2,H26,H38,H50) | I14: =CHOOSE('Болжамдар'!$D$2,I26,I38,I50) | J14: =CHOOSE('Болжамдар'!$D$2,J26,J38,J50) | K14: =CHOOSE('Болжамдар'!$D$2,K26,K38,K50) | ... AM14: =CHOOSE('Болжамдар'!$D$2,AM26,AM38,AM50)
A17: Сценарий: Консервативті
A18: Жаңа лид | B18: мектеп | C18: =SUM(D18:AM18) | D18: =N('Болжамдар'!$C$10) | E18: =N('Болжамдар'!$C$10) | F18: =N('Болжамдар'!$C$10) | G18: =N('Болжамдар'!$C$10) | H18: =N('Болжамдар'!$C$10) | I18: =N('Болжамдар'!$C$10) | J18: =N('Болжамдар'!$C$10) | K18: =N('Болжамдар'!$C$10) | ... AM18: =N('Болжамдар'!$C$10)
A19: Жаңа пилот | B19: мектеп | C19: =SUM(D19:AM19) | D19: =D18*N('Болжамдар'!$C$11) | E19: =E18*N('Болжамдар'!$C$11) | F19: =F18*N('Болжамдар'!$C$11) | G19: =G18*N('Болжамдар'!$C$11) | H19: =H18*N('Болжамдар'!$C$11) | I19: =I18*N('Болжамдар'!$C$11) | J19: =J18*N('Болжамдар'!$C$11) | K19: =K18*N('Болжамдар'!$C$11) | ... AM19: =AM18*N('Болжамдар'!$C$11)
A20: Жаңа төлеуші мектеп | B20: мектеп | C20: =SUM(D20:AM20) | D20: =IF(D$4>N('Болжамдар'!$C$13),INDEX($D19:$AM19,1,MAX(1,D$4-N('Болжамдар'!$C$13))),0)*N('Болжамдар'!$C$12)+IF(D$4=1,N('Болжамдар'!$C$8),0) | E20: =IF(E$4>N('Болжамдар'!$C$13),INDEX($D19:$AM19,1,MAX(1,E$4-N('Болжамдар'!$C$13))),0)*N('Болжамдар'!$C$12)+IF(E$4=1,N('Болжамдар'!$C$8),0) | F20: =IF(F$4>N('Болжамдар'!$C$13),INDEX($D19:$AM19,1,MAX(1,F$4-N('Болжамдар'!$C$13))),0)*N('Болжамдар'!$C$12)+IF(F$4=1,N('Болжамдар'!$C$8),0) | G20: =IF(G$4>N('Болжамдар'!$C$13),INDEX($D19:$AM19,1,MAX(1,G$4-N('Болжамдар'!$C$13))),0)*N('Болжамдар'!$C$12)+IF(G$4=1,N('Болжамдар'!$C$8),0) | H20: =IF(H$4>N('Болжамдар'!$C$13),INDEX($D19:$AM19,1,MAX(1,H$4-N('Болжамдар'!$C$13))),0)*N('Болжамдар'!$C$12)+IF(H$4=1,N('Болжамдар'!$C$8),0) | I20: =IF(I$4>N('Болжамдар'!$C$13),INDEX($D19:$AM19,1,MAX(1,I$4-N('Болжамдар'!$C$13))),0)*N('Болжамдар'!$C$12)+IF(I$4=1,N('Болжамдар'!$C$8),0) | J20: =IF(J$4>N('Болжамдар'!$C$13),INDEX($D19:$AM19,1,MAX(1,J$4-N('Болжамдар'!$C$13))),0)*N('Болжамдар'!$C$12)+IF(J$4=1,N('Болжамдар'!$C$8),0) | K20: =IF(K$4>N('Болжамдар'!$C$13),INDEX($D19:$AM19,1,MAX(1,K$4-N('Болжамдар'!$C$13))),0)*N('Болжамдар'!$C$12)+IF(K$4=1,N('Болжамдар'!$C$8),0) | ... AM20: =IF(AM$4>N('Болжамдар'!$C$13),INDEX($D19:$AM19,1,MAX(1,AM$4-N('Болжамдар'!$C$13))),0)*N('Болжамдар'!$C$12)+IF(AM$4=1,N('Болжамдар'!$C$8),0)
A21: Кеткен (churn) мектеп | B21: мектеп | C21: =SUM(D21:AM21) | D21: =IF(D$4=1,0,0) | E21: =D22*N('Болжамдар'!$C$14) | F21: =E22*N('Болжамдар'!$C$14) | G21: =F22*N('Болжамдар'!$C$14) | H21: =G22*N('Болжамдар'!$C$14) | I21: =H22*N('Болжамдар'!$C$14) | J21: =I22*N('Болжамдар'!$C$14) | K21: =J22*N('Болжамдар'!$C$14) | L21: =K22*N('Болжамдар'!$C$14) | ... AM21: =AL22*N('Болжамдар'!$C$14)
A22: Белсенді төлеуші мектеп | B22: мектеп | C22: =AM22 | D22: =0+D20-D21 | E22: =D22+E20-E21 | F22: =E22+F20-F21 | G22: =F22+G20-G21 | H22: =G22+H20-H21 | I22: =H22+I20-I21 | J22: =I22+J20-J21 | K22: =J22+K20-K21 | L22: =K22+L20-L21 | ... AM22: =AL22+AM20-AM21
A23: Төлеуші оқушылар | B23: оқушы | C23: =AM23 | D23: =D22*N('Болжамдар'!$C$7) | E23: =E22*N('Болжамдар'!$C$7) | F23: =F22*N('Болжамдар'!$C$7) | G23: =G22*N('Болжамдар'!$C$7) | H23: =H22*N('Болжамдар'!$C$7) | I23: =I22*N('Болжамдар'!$C$7) | J23: =J22*N('Болжамдар'!$C$7) | K23: =K22*N('Болжамдар'!$C$7) | ... AM23: =AM22*N('Болжамдар'!$C$7)
A24: MRR | B24: ₸/ай | C24: =AM24 | D24: =D23*N('Болжамдар'!$C$6)/12 | E24: =E23*N('Болжамдар'!$C$6)/12 | F24: =F23*N('Болжамдар'!$C$6)/12 | G24: =G23*N('Болжамдар'!$C$6)/12 | H24: =H23*N('Болжамдар'!$C$6)/12 | I24: =I23*N('Болжамдар'!$C$6)/12 | J24: =J23*N('Болжамдар'!$C$6)/12 | K24: =K23*N('Болжамдар'!$C$6)/12 | ... AM24: =AM23*N('Болжамдар'!$C$6)/12
A25: ARR (= MRR x 12) | B25: ₸/жыл | C25: =AM25 | D25: =D24*12 | E25: =E24*12 | F25: =F24*12 | G25: =G24*12 | H25: =H24*12 | I25: =I24*12 | J25: =J24*12 | K25: =K24*12 | ... AM25: =AM24*12
A26: Кіріс (ай) | B26: ₸ | C26: =SUM(D26:AM26) | D26: =D24 | E26: =E24 | F26: =F24 | G26: =G24 | H26: =H24 | I26: =I24 | J26: =J24 | K26: =K24 | ... AM26: =AM24
A29: Сценарий: Базалық
A30: Жаңа лид | B30: мектеп | C30: =SUM(D30:AM30) | D30: =N('Болжамдар'!$D$10) | E30: =N('Болжамдар'!$D$10) | F30: =N('Болжамдар'!$D$10) | G30: =N('Болжамдар'!$D$10) | H30: =N('Болжамдар'!$D$10) | I30: =N('Болжамдар'!$D$10) | J30: =N('Болжамдар'!$D$10) | K30: =N('Болжамдар'!$D$10) | ... AM30: =N('Болжамдар'!$D$10)
A31: Жаңа пилот | B31: мектеп | C31: =SUM(D31:AM31) | D31: =D30*N('Болжамдар'!$D$11) | E31: =E30*N('Болжамдар'!$D$11) | F31: =F30*N('Болжамдар'!$D$11) | G31: =G30*N('Болжамдар'!$D$11) | H31: =H30*N('Болжамдар'!$D$11) | I31: =I30*N('Болжамдар'!$D$11) | J31: =J30*N('Болжамдар'!$D$11) | K31: =K30*N('Болжамдар'!$D$11) | ... AM31: =AM30*N('Болжамдар'!$D$11)
A32: Жаңа төлеуші мектеп | B32: мектеп | C32: =SUM(D32:AM32) | D32: =IF(D$4>N('Болжамдар'!$D$13),INDEX($D31:$AM31,1,MAX(1,D$4-N('Болжамдар'!$D$13))),0)*N('Болжамдар'!$D$12)+IF(D$4=1,N('Болжамдар'!$D$8),0) | E32: =IF(E$4>N('Болжамдар'!$D$13),INDEX($D31:$AM31,1,MAX(1,E$4-N('Болжамдар'!$D$13))),0)*N('Болжамдар'!$D$12)+IF(E$4=1,N('Болжамдар'!$D$8),0) | F32: =IF(F$4>N('Болжамдар'!$D$13),INDEX($D31:$AM31,1,MAX(1,F$4-N('Болжамдар'!$D$13))),0)*N('Болжамдар'!$D$12)+IF(F$4=1,N('Болжамдар'!$D$8),0) | G32: =IF(G$4>N('Болжамдар'!$D$13),INDEX($D31:$AM31,1,MAX(1,G$4-N('Болжамдар'!$D$13))),0)*N('Болжамдар'!$D$12)+IF(G$4=1,N('Болжамдар'!$D$8),0) | H32: =IF(H$4>N('Болжамдар'!$D$13),INDEX($D31:$AM31,1,MAX(1,H$4-N('Болжамдар'!$D$13))),0)*N('Болжамдар'!$D$12)+IF(H$4=1,N('Болжамдар'!$D$8),0) | I32: =IF(I$4>N('Болжамдар'!$D$13),INDEX($D31:$AM31,1,MAX(1,I$4-N('Болжамдар'!$D$13))),0)*N('Болжамдар'!$D$12)+IF(I$4=1,N('Болжамдар'!$D$8),0) | J32: =IF(J$4>N('Болжамдар'!$D$13),INDEX($D31:$AM31,1,MAX(1,J$4-N('Болжамдар'!$D$13))),0)*N('Болжамдар'!$D$12)+IF(J$4=1,N('Болжамдар'!$D$8),0) | K32: =IF(K$4>N('Болжамдар'!$D$13),INDEX($D31:$AM31,1,MAX(1,K$4-N('Болжамдар'!$D$13))),0)*N('Болжамдар'!$D$12)+IF(K$4=1,N('Болжамдар'!$D$8),0) | ... AM32: =IF(AM$4>N('Болжамдар'!$D$13),INDEX($D31:$AM31,1,MAX(1,AM$4-N('Болжамдар'!$D$13))),0)*N('Болжамдар'!$D$12)+IF(AM$4=1,N('Болжамдар'!$D$8),0)
A33: Кеткен (churn) мектеп | B33: мектеп | C33: =SUM(D33:AM33) | D33: =IF(D$4=1,0,0) | E33: =D34*N('Болжамдар'!$D$14) | F33: =E34*N('Болжамдар'!$D$14) | G33: =F34*N('Болжамдар'!$D$14) | H33: =G34*N('Болжамдар'!$D$14) | I33: =H34*N('Болжамдар'!$D$14) | J33: =I34*N('Болжамдар'!$D$14) | K33: =J34*N('Болжамдар'!$D$14) | L33: =K34*N('Болжамдар'!$D$14) | ... AM33: =AL34*N('Болжамдар'!$D$14)
A34: Белсенді төлеуші мектеп | B34: мектеп | C34: =AM34 | D34: =0+D32-D33 | E34: =D34+E32-E33 | F34: =E34+F32-F33 | G34: =F34+G32-G33 | H34: =G34+H32-H33 | I34: =H34+I32-I33 | J34: =I34+J32-J33 | K34: =J34+K32-K33 | L34: =K34+L32-L33 | ... AM34: =AL34+AM32-AM33
A35: Төлеуші оқушылар | B35: оқушы | C35: =AM35 | D35: =D34*N('Болжамдар'!$D$7) | E35: =E34*N('Болжамдар'!$D$7) | F35: =F34*N('Болжамдар'!$D$7) | G35: =G34*N('Болжамдар'!$D$7) | H35: =H34*N('Болжамдар'!$D$7) | I35: =I34*N('Болжамдар'!$D$7) | J35: =J34*N('Болжамдар'!$D$7) | K35: =K34*N('Болжамдар'!$D$7) | ... AM35: =AM34*N('Болжамдар'!$D$7)
A36: MRR | B36: ₸/ай | C36: =AM36 | D36: =D35*N('Болжамдар'!$D$6)/12 | E36: =E35*N('Болжамдар'!$D$6)/12 | F36: =F35*N('Болжамдар'!$D$6)/12 | G36: =G35*N('Болжамдар'!$D$6)/12 | H36: =H35*N('Болжамдар'!$D$6)/12 | I36: =I35*N('Болжамдар'!$D$6)/12 | J36: =J35*N('Болжамдар'!$D$6)/12 | K36: =K35*N('Болжамдар'!$D$6)/12 | ... AM36: =AM35*N('Болжамдар'!$D$6)/12
A37: ARR (= MRR x 12) | B37: ₸/жыл | C37: =AM37 | D37: =D36*12 | E37: =E36*12 | F37: =F36*12 | G37: =G36*12 | H37: =H36*12 | I37: =I36*12 | J37: =J36*12 | K37: =K36*12 | ... AM37: =AM36*12
A38: Кіріс (ай) | B38: ₸ | C38: =SUM(D38:AM38) | D38: =D36 | E38: =E36 | F38: =F36 | G38: =G36 | H38: =H36 | I38: =I36 | J38: =J36 | K38: =K36 | ... AM38: =AM36
A41: Сценарий: Оптимистік
A42: Жаңа лид | B42: мектеп | C42: =SUM(D42:AM42) | D42: =N('Болжамдар'!$E$10) | E42: =N('Болжамдар'!$E$10) | F42: =N('Болжамдар'!$E$10) | G42: =N('Болжамдар'!$E$10) | H42: =N('Болжамдар'!$E$10) | I42: =N('Болжамдар'!$E$10) | J42: =N('Болжамдар'!$E$10) | K42: =N('Болжамдар'!$E$10) | ... AM42: =N('Болжамдар'!$E$10)
A43: Жаңа пилот | B43: мектеп | C43: =SUM(D43:AM43) | D43: =D42*N('Болжамдар'!$E$11) | E43: =E42*N('Болжамдар'!$E$11) | F43: =F42*N('Болжамдар'!$E$11) | G43: =G42*N('Болжамдар'!$E$11) | H43: =H42*N('Болжамдар'!$E$11) | I43: =I42*N('Болжамдар'!$E$11) | J43: =J42*N('Болжамдар'!$E$11) | K43: =K42*N('Болжамдар'!$E$11) | ... AM43: =AM42*N('Болжамдар'!$E$11)
A44: Жаңа төлеуші мектеп | B44: мектеп | C44: =SUM(D44:AM44) | D44: =IF(D$4>N('Болжамдар'!$E$13),INDEX($D43:$AM43,1,MAX(1,D$4-N('Болжамдар'!$E$13))),0)*N('Болжамдар'!$E$12)+IF(D$4=1,N('Болжамдар'!$E$8),0) | E44: =IF(E$4>N('Болжамдар'!$E$13),INDEX($D43:$AM43,1,MAX(1,E$4-N('Болжамдар'!$E$13))),0)*N('Болжамдар'!$E$12)+IF(E$4=1,N('Болжамдар'!$E$8),0) | F44: =IF(F$4>N('Болжамдар'!$E$13),INDEX($D43:$AM43,1,MAX(1,F$4-N('Болжамдар'!$E$13))),0)*N('Болжамдар'!$E$12)+IF(F$4=1,N('Болжамдар'!$E$8),0) | G44: =IF(G$4>N('Болжамдар'!$E$13),INDEX($D43:$AM43,1,MAX(1,G$4-N('Болжамдар'!$E$13))),0)*N('Болжамдар'!$E$12)+IF(G$4=1,N('Болжамдар'!$E$8),0) | H44: =IF(H$4>N('Болжамдар'!$E$13),INDEX($D43:$AM43,1,MAX(1,H$4-N('Болжамдар'!$E$13))),0)*N('Болжамдар'!$E$12)+IF(H$4=1,N('Болжамдар'!$E$8),0) | I44: =IF(I$4>N('Болжамдар'!$E$13),INDEX($D43:$AM43,1,MAX(1,I$4-N('Болжамдар'!$E$13))),0)*N('Болжамдар'!$E$12)+IF(I$4=1,N('Болжамдар'!$E$8),0) | J44: =IF(J$4>N('Болжамдар'!$E$13),INDEX($D43:$AM43,1,MAX(1,J$4-N('Болжамдар'!$E$13))),0)*N('Болжамдар'!$E$12)+IF(J$4=1,N('Болжамдар'!$E$8),0) | K44: =IF(K$4>N('Болжамдар'!$E$13),INDEX($D43:$AM43,1,MAX(1,K$4-N('Болжамдар'!$E$13))),0)*N('Болжамдар'!$E$12)+IF(K$4=1,N('Болжамдар'!$E$8),0) | ... AM44: =IF(AM$4>N('Болжамдар'!$E$13),INDEX($D43:$AM43,1,MAX(1,AM$4-N('Болжамдар'!$E$13))),0)*N('Болжамдар'!$E$12)+IF(AM$4=1,N('Болжамдар'!$E$8),0)
A45: Кеткен (churn) мектеп | B45: мектеп | C45: =SUM(D45:AM45) | D45: =IF(D$4=1,0,0) | E45: =D46*N('Болжамдар'!$E$14) | F45: =E46*N('Болжамдар'!$E$14) | G45: =F46*N('Болжамдар'!$E$14) | H45: =G46*N('Болжамдар'!$E$14) | I45: =H46*N('Болжамдар'!$E$14) | J45: =I46*N('Болжамдар'!$E$14) | K45: =J46*N('Болжамдар'!$E$14) | L45: =K46*N('Болжамдар'!$E$14) | ... AM45: =AL46*N('Болжамдар'!$E$14)
A46: Белсенді төлеуші мектеп | B46: мектеп | C46: =AM46 | D46: =0+D44-D45 | E46: =D46+E44-E45 | F46: =E46+F44-F45 | G46: =F46+G44-G45 | H46: =G46+H44-H45 | I46: =H46+I44-I45 | J46: =I46+J44-J45 | K46: =J46+K44-K45 | L46: =K46+L44-L45 | ... AM46: =AL46+AM44-AM45
A47: Төлеуші оқушылар | B47: оқушы | C47: =AM47 | D47: =D46*N('Болжамдар'!$E$7) | E47: =E46*N('Болжамдар'!$E$7) | F47: =F46*N('Болжамдар'!$E$7) | G47: =G46*N('Болжамдар'!$E$7) | H47: =H46*N('Болжамдар'!$E$7) | I47: =I46*N('Болжамдар'!$E$7) | J47: =J46*N('Болжамдар'!$E$7) | K47: =K46*N('Болжамдар'!$E$7) | ... AM47: =AM46*N('Болжамдар'!$E$7)
...

Sheet Шығын
A1: Шығын (белсенді сценарий, 36 ай)
A2: ГИПОТЕЗА: шығын мөлшері Болжамдар парағынан; толтырылмаса 0.
A4: Шығын түрі | B4: Бірлік | C4: Жиыны / соңы | D4: 1 | E4: =D4+1 | F4: =E4+1 | G4: =F4+1 | H4: =G4+1 | I4: =H4+1 | J4: =I4+1 | K4: =J4+1 | L4: =K4+1 | ... AM4: =AL4+1
A5: Белсенді төлеуші мектеп | B5: мектеп | C5: =AM5 | D5: ='Кіріс'!D10 | E5: ='Кіріс'!E10 | F5: ='Кіріс'!F10 | G5: ='Кіріс'!G10 | H5: ='Кіріс'!H10 | I5: ='Кіріс'!I10 | J5: ='Кіріс'!J10 | K5: ='Кіріс'!K10 | ... AM5: ='Кіріс'!AM10
A6: Кіріс | B6: ₸ | C6: =SUM(D6:AM6) | D6: ='Кіріс'!D14 | E6: ='Кіріс'!E14 | F6: ='Кіріс'!F14 | G6: ='Кіріс'!G14 | H6: ='Кіріс'!H14 | I6: ='Кіріс'!I14 | J6: ='Кіріс'!J14 | K6: ='Кіріс'!K14 | ... AM6: ='Кіріс'!AM14
A7: Хостинг: ауыспалы (мектепке) | B7: ₸ | C7: =SUM(D7:AM7) | D7: =D5*N('Болжамдар'!$F$16) | E7: =E5*N('Болжамдар'!$F$16) | F7: =F5*N('Болжамдар'!$F$16) | G7: =G5*N('Болжамдар'!$F$16) | H7: =H5*N('Болжамдар'!$F$16) | I7: =I5*N('Болжамдар'!$F$16) | J7: =J5*N('Болжамдар'!$F$16) | K7: =K5*N('Болжамдар'!$F$16) | ... AM7: =AM5*N('Болжамдар'!$F$16)
A8: Хостинг: тұрақты | B8: ₸ | C8: =SUM(D8:AM8) | D8: =N('Болжамдар'!$F$21) | E8: =N('Болжамдар'!$F$21) | F8: =N('Болжамдар'!$F$21) | G8: =N('Болжамдар'!$F$21) | H8: =N('Болжамдар'!$F$21) | I8: =N('Болжамдар'!$F$21) | J8: =N('Болжамдар'!$F$21) | K8: =N('Болжамдар'!$F$21) | ... AM8: =N('Болжамдар'!$F$21)
A9: Қолдау (сағат x құны) | B9: ₸ | C9: =SUM(D9:AM9) | D9: =D5*N('Болжамдар'!$F$17)*N('Болжамдар'!$F$18) | E9: =E5*N('Болжамдар'!$F$17)*N('Болжамдар'!$F$18) | F9: =F5*N('Болжамдар'!$F$17)*N('Болжамдар'!$F$18) | G9: =G5*N('Болжамдар'!$F$17)*N('Болжамдар'!$F$18) | H9: =H5*N('Болжамдар'!$F$17)*N('Болжамдар'!$F$18) | I9: =I5*N('Болжамдар'!$F$17)*N('Болжамдар'!$F$18) | J9: =J5*N('Болжамдар'!$F$17)*N('Болжамдар'!$F$18) | K9: =K5*N('Болжамдар'!$F$17)*N('Болжамдар'!$F$18) | ... AM9: =AM5*N('Болжамдар'!$F$17)*N('Болжамдар'!$F$18)
A10: Жалақы | B10: ₸ | C10: =SUM(D10:AM10) | D10: =N('Болжамдар'!$F$22)*N('Болжамдар'!$F$23) | E10: =N('Болжамдар'!$F$22)*N('Болжамдар'!$F$23) | F10: =N('Болжамдар'!$F$22)*N('Болжамдар'!$F$23) | G10: =N('Болжамдар'!$F$22)*N('Болжамдар'!$F$23) | H10: =N('Болжамдар'!$F$22)*N('Болжамдар'!$F$23) | I10: =N('Болжамдар'!$F$22)*N('Болжамдар'!$F$23) | J10: =N('Болжамдар'!$F$22)*N('Болжамдар'!$F$23) | K10: =N('Болжамдар'!$F$22)*N('Болжамдар'!$F$23) | ... AM10: =N('Болжамдар'!$F$22)*N('Болжамдар'!$F$23)
A11: Заңгер | B11: ₸ | C11: =SUM(D11:AM11) | D11: =N('Болжамдар'!$F$24) | E11: =N('Болжамдар'!$F$24) | F11: =N('Болжамдар'!$F$24) | G11: =N('Болжамдар'!$F$24) | H11: =N('Болжамдар'!$F$24) | I11: =N('Болжамдар'!$F$24) | J11: =N('Болжамдар'!$F$24) | K11: =N('Болжамдар'!$F$24) | ... AM11: =N('Болжамдар'!$F$24)
A12: Маркетинг және сату | B12: ₸ | C12: =SUM(D12:AM12) | D12: =N('Болжамдар'!$F$25) | E12: =N('Болжамдар'!$F$25) | F12: =N('Болжамдар'!$F$25) | G12: =N('Болжамдар'!$F$25) | H12: =N('Болжамдар'!$F$25) | I12: =N('Болжамдар'!$F$25) | J12: =N('Болжамдар'!$F$25) | K12: =N('Болжамдар'!$F$25) | ... AM12: =N('Болжамдар'!$F$25)
A13: Төлем комиссиясы және салық | B13: ₸ | C13: =SUM(D13:AM13) | D13: =D6*N('Болжамдар'!$F$19) | E13: =E6*N('Болжамдар'!$F$19) | F13: =F6*N('Болжамдар'!$F$19) | G13: =G6*N('Болжамдар'!$F$19) | H13: =H6*N('Болжамдар'!$F$19) | I13: =I6*N('Болжамдар'!$F$19) | J13: =J6*N('Болжамдар'!$F$19) | K13: =K6*N('Болжамдар'!$F$19) | ... AM13: =AM6*N('Болжамдар'!$F$19)
A14: ЖИЫНЫ шығын | B14: ₸ | C14: =SUM(D14:AM14) | D14: =SUM(D7:D13) | E14: =SUM(E7:E13) | F14: =SUM(F7:F13) | G14: =SUM(G7:G13) | H14: =SUM(H7:H13) | I14: =SUM(I7:I13) | J14: =SUM(J7:J13) | K14: =SUM(K7:K13) | ... AM14: =SUM(AM7:AM13)

Sheet P&L
A1: P&L (белсенді сценарий)
A2: ГИПОТЕЗА: барлық сан формуладан; Болжамдар толтырылмаса 0.
A4: Жылдық қорытынды | B4: Бірлік | C4: 1-жыл | D4: 2-жыл | E4: 3-жыл
A5: Кіріс | B5: ₸ | C5: =SUM(D20:O20) | D5: =SUM(P20:AA20) | E5: =SUM(AB20:AM20)
A6: Тікелей шығын | B6: ₸ | C6: =SUM(D21:O21) | D6: =SUM(P21:AA21) | E6: =SUM(AB21:AM21)
A7: Жалпы пайда | B7: ₸ | C7: =SUM(D22:O22) | D7: =SUM(P22:AA22) | E7: =SUM(AB22:AM22)
A8: Операциялық шығын | B8: ₸ | C8: =SUM(D24:O24) | D8: =SUM(P24:AA24) | E8: =SUM(AB24:AM24)
A9: Комиссия және салық | B9: ₸ | C9: =SUM(D25:O25) | D9: =SUM(P25:AA25) | E9: =SUM(AB25:AM25)
A10: Таза нәтиже | B10: ₸ | C10: =SUM(D26:O26) | D10: =SUM(P26:AA26) | E10: =SUM(AB26:AM26)
A11: Жалпы маржа | B11: % | C11: =IFERROR(C7/C5,0) | D11: =IFERROR(D7/D5,0) | E11: =IFERROR(E7/E5,0)
A13: Сценарий салыстыруы (тек кіріс жағы) | B13: Бірлік | C13: Консервативті | D13: Базалық | E13: Оптимистік
A14: 36-ай ARR | B14: ₸ | C14: ='Кіріс'!C25 | D14: ='Кіріс'!C37 | E14: ='Кіріс'!C49
A15: 36-айдағы төлеуші мектеп | B15: мектеп | C15: ='Кіріс'!C22 | D15: ='Кіріс'!C34 | E15: ='Кіріс'!C46
A16: 36 айдағы жиынтық кіріс | B16: ₸ | C16: ='Кіріс'!C26 | D16: ='Кіріс'!C38 | E16: ='Кіріс'!C50
A19: Айлық P&L | B19: Бірлік | C19: Жиыны / соңы | D19: 1 | E19: =D19+1 | F19: =E19+1 | G19: =F19+1 | H19: =G19+1 | I19: =H19+1 | J19: =I19+1 | K19: =J19+1 | L19: =K19+1 | ... AM19: =AL19+1
A20: Кіріс | B20: ₸ | C20: =SUM(D20:AM20) | D20: ='Шығын'!D6 | E20: ='Шығын'!E6 | F20: ='Шығын'!F6 | G20: ='Шығын'!G6 | H20: ='Шығын'!H6 | I20: ='Шығын'!I6 | J20: ='Шығын'!J6 | K20: ='Шығын'!K6 | ... AM20: ='Шығын'!AM6
A21: Тікелей шығын (хостинг + қолдау) | B21: ₸ | C21: =SUM(D21:AM21) | D21: ='Шығын'!D7+'Шығын'!D8+'Шығын'!D9 | E21: ='Шығын'!E7+'Шығын'!E8+'Шығын'!E9 | F21: ='Шығын'!F7+'Шығын'!F8+'Шығын'!F9 | G21: ='Шығын'!G7+'Шығын'!G8+'Шығын'!G9 | H21: ='Шығын'!H7+'Шығын'!H8+'Шығын'!H9 | I21: ='Шығын'!I7+'Шығын'!I8+'Шығын'!I9 | J21: ='Шығын'!J7+'Шығын'!J8+'Шығын'!J9 | K21: ='Шығын'!K7+'Шығын'!K8+'Шығын'!K9 | ... AM21: ='Шығын'!AM7+'Шығын'!AM8+'Шығын'!AM9
A22: Жалпы пайда | B22: ₸ | C22: =SUM(D22:AM22) | D22: =D20-D21 | E22: =E20-E21 | F22: =F20-F21 | G22: =G20-G21 | H22: =H20-H21 | I22: =I20-I21 | J22: =J20-J21 | K22: =K20-K21 | ... AM22: =AM20-AM21
A23: Жалпы маржа | B23: % | C23: =IFERROR(C22/C20,0) | D23: =IFERROR(D22/D20,0) | E23: =IFERROR(E22/E20,0) | F23: =IFERROR(F22/F20,0) | G23: =IFERROR(G22/G20,0) | H23: =IFERROR(H22/H20,0) | I23: =IFERROR(I22/I20,0) | J23: =IFERROR(J22/J20,0) | ... AM23: =IFERROR(AM22/AM20,0)
A24: Операциялық шығын (жалақы, заңгер, маркетинг) | B24: ₸ | C24: =SUM(D24:AM24) | D24: ='Шығын'!D10+'Шығын'!D11+'Шығын'!D12 | E24: ='Шығын'!E10+'Шығын'!E11+'Шығын'!E12 | F24: ='Шығын'!F10+'Шығын'!F11+'Шығын'!F12 | G24: ='Шығын'!G10+'Шығын'!G11+'Шығын'!G12 | H24: ='Шығын'!H10+'Шығын'!H11+'Шығын'!H12 | I24: ='Шығын'!I10+'Шығын'!I11+'Шығын'!I12 | J24: ='Шығын'!J10+'Шығын'!J11+'Шығын'!J12 | K24: ='Шығын'!K10+'Шығын'!K11+'Шығын'!K12 | ... AM24: ='Шығын'!AM10+'Шығын'!AM11+'Шығын'!AM12
A25: Комиссия және салық | B25: ₸ | C25: =SUM(D25:AM25) | D25: ='Шығын'!D13 | E25: ='Шығын'!E13 | F25: ='Шығын'!F13 | G25: ='Шығын'!G13 | H25: ='Шығын'!H13 | I25: ='Шығын'!I13 | J25: ='Шығын'!J13 | K25: ='Шығын'!K13 | ... AM25: ='Шығын'!AM13
A26: Таза нәтиже (EBITDA-ға жақын) | B26: ₸ | C26: =SUM(D26:AM26) | D26: =D22-D24-D25 | E26: =E22-E24-E25 | F26: =F22-F24-F25 | G26: =G22-G24-G25 | H26: =H22-H24-H25 | I26: =I22-I24-I25 | J26: =J22-J24-J25 | K26: =K22-K24-K25 | ... AM26: =AM22-AM24-AM25

Sheet Cash және runway
A1: Cash және runway (белсенді сценарий)
A2: ГИПОТЕЗА: бастапқы касса Болжамдар парағында; бос болса 0.
A4: Көрсеткіш | B4: Бірлік | C4: Жиыны / соңы | D4: 1 | E4: =D4+1 | F4: =E4+1 | G4: =F4+1 | H4: =G4+1 | I4: =H4+1 | J4: =I4+1 | K4: =J4+1 | L4: =K4+1 | ... AM4: =AL4+1
A5: Ай басындағы касса | B5: ₸ | D5: =N('Болжамдар'!$F$27) | E5: =D7 | F5: =E7 | G5: =F7 | H5: =G7 | I5: =H7 | J5: =I7 | K5: =J7 | L5: =K7 | ... AM5: =AL7
A6: Таза нәтиже (P&L) | B6: ₸ | C6: =SUM(D6:AM6) | D6: ='P&L'!D26 | E6: ='P&L'!E26 | F6: ='P&L'!F26 | G6: ='P&L'!G26 | H6: ='P&L'!H26 | I6: ='P&L'!I26 | J6: ='P&L'!J26 | K6: ='P&L'!K26 | ... AM6: ='P&L'!AM26
A7: Ай соңындағы касса | B7: ₸ | C7: =AM7 | D7: =D5+D6 | E7: =E5+E6 | F7: =F5+F6 | G7: =G5+G6 | H7: =H5+H6 | I7: =I5+I6 | J7: =J5+J6 | K7: =K5+K6 | ... AM7: =AM5+AM6
A8: Burn (таза шығыс) | B8: ₸ | C8: =SUM(D8:AM8) | D8: =MAX(0,-D6) | E8: =MAX(0,-E6) | F8: =MAX(0,-F6) | G8: =MAX(0,-G6) | H8: =MAX(0,-H6) | I8: =MAX(0,-I6) | J8: =MAX(0,-J6) | K8: =MAX(0,-K6) | ... AM8: =MAX(0,-AM6)
A9: Орташа burn (соңғы 3 ай) | B9: ₸ | D9: =AVERAGE(D8:D8) | E9: =AVERAGE(D8:E8) | F9: =AVERAGE(D8:F8) | G9: =AVERAGE(E8:G8) | H9: =AVERAGE(F8:H8) | I9: =AVERAGE(G8:I8) | J9: =AVERAGE(H8:J8) | K9: =AVERAGE(I8:K8) | L9: =AVERAGE(J8:L8) | M9: =AVERAGE(K8:M8) | ... AM9: =AVERAGE(AK8:AM8)
A10: Runway (ай) | B10: ай | D10: =IF(D7<=0,0,IFERROR(D7/D9,"-")) | E10: =IF(E7<=0,0,IFERROR(E7/E9,"-")) | F10: =IF(F7<=0,0,IFERROR(F7/F9,"-")) | G10: =IF(G7<=0,0,IFERROR(G7/G9,"-")) | H10: =IF(H7<=0,0,IFERROR(H7/H9,"-")) | I10: =IF(I7<=0,0,IFERROR(I7/I9,"-")) | J10: =IF(J7<=0,0,IFERROR(J7/J9,"-")) | K10: =IF(K7<=0,0,IFERROR(K7/K9,"-")) | ... AM10: =IF(AM7<=0,0,IFERROR(AM7/AM9,"-"))
A11: Касса теріс (1 = иә) | B11: флаг | C11: =SUM(D11:AM11) | D11: =IF(D7<0,1,0) | E11: =IF(E7<0,1,0) | F11: =IF(F7<0,1,0) | G11: =IF(G7<0,1,0) | H11: =IF(H7<0,1,0) | I11: =IF(I7<0,1,0) | J11: =IF(J7<0,1,0) | K11: =IF(K7<0,1,0) | ... AM11: =IF(AM7<0,1,0)
A14: Ең төмен касса деңгейі | C14: =MIN(D7:AM7)
A15: Касса теріс болатын алғашқы ай | C15: =IFERROR(MATCH(1,D11:AM11,0),"жоқ")
A16: Қосымша қаржы қажеттілігі (ең төмен касса теріс болса) | C16: =MAX(0,-C14)
A17: 36-ай соңындағы касса | C17: =AM7
A18: Ескерту: runway 3 айлық орташа burn бойынша; пайдалы ай болса '-' (burn жоқ).

Sheet Бірлік экономикасы
A1: Бірлік экономикасы (белсенді сценарий)
A2: ГИПОТЕЗА: барлығы Болжамдардан; бөлгіш 0 болса '-' шығады (қате емес).
A4: Көрсеткіш | B4: Бірлік | C4: Мәні | D4: Формула / түсінік
A5: ARPA: 1 мектептен ай сайынғы кіріс | B5: ₸/ай | C5: =N('Болжамдар'!$F$7)*N('Болжамдар'!$F$6)/12 | D5: оқушы x баға / 12
A6: Хостинг (ауыспалы) / мектеп | B6: ₸/ай | C6: =N('Болжамдар'!$F$16)
A7: Қолдау / мектеп | B7: ₸/ай | C7: =N('Болжамдар'!$F$17)*N('Болжамдар'!$F$18) | D7: сағат x сағат құны
A8: Комиссия және салық / мектеп | B8: ₸/ай | C8: =C5*N('Болжамдар'!$F$19) | D8: ARPA x %
A9: Жарна маржасы / мектеп | B9: ₸/ай | C9: =C5-C6-C7-C8 | D9: ARPA - ауыспалы шығындар
A10: Айлық churn | B10: % | C10: =N('Болжамдар'!$F$14)
A11: Күтілетін өмір ұзақтығы | B11: ай | C11: =IFERROR(1/C10,"-") | D11: 1 / churn (churn = 0 болса '-')
A12: LTV (жарна маржасы бойынша) | B12: ₸ | C12: =IFERROR(C9/C10,"-") | D12: жарна маржасы / churn
A13: CAC: 1 жаңа төлеуші мектепке сату шығыны | B13: ₸ | C13: =IFERROR('Шығын'!C12/'Кіріс'!C8,"-") | D13: 36 ай маркетингі / 36 айдағы жаңа төлеуші мектеп
A14: LTV / CAC | B14: x | C14: =IFERROR(C12/C13,"-")
A15: CAC өтелу мерзімі (payback) | B15: ай | C15: =IFERROR(C13/C9,"-") | D15: CAC / айлық жарна маржасы
A16: Орташа тұрақты шығын | B16: ₸/ай | C16: =('Шығын'!C8+'Шығын'!C10+'Шығын'!C11+'Шығын'!C12)/36 | D16: 36 айдың орташасы
A17: Нөлге шығу үшін мектеп саны (break-even) | B17: мектеп | C17: =IFERROR(C16/C9,"-") | D17: тұрақты шығын / жарна маржасы

Sheet Сезімталдық кестесі
A1: Сезімталдық кестесі (белсенді сценарий)
A2: Көлденең/тік ось мәндерін ӨЗІҢІЗ енгізіңіз (ГИПОТЕЗА). Бос ось = 0.
A4: 1) 36-айдағы ARR (₸): белсенді мектеп x оқушы x баға
A5: Баға (₸/оқушы/жыл) ↓ | Оқушы/мектеп →
B6: =N('Кіріс'!$C$10)*N(B$5)*N($A6) | C6: =N('Кіріс'!$C$10)*N(C$5)*N($A6) | D6: =N('Кіріс'!$C$10)*N(D$5)*N($A6) | E6: =N('Кіріс'!$C$10)*N(E$5)*N($A6) | F6: =N('Кіріс'!$C$10)*N(F$5)*N($A6)
B7: =N('Кіріс'!$C$10)*N(B$5)*N($A7) | C7: =N('Кіріс'!$C$10)*N(C$5)*N($A7) | D7: =N('Кіріс'!$C$10)*N(D$5)*N($A7) | E7: =N('Кіріс'!$C$10)*N(E$5)*N($A7) | F7: =N('Кіріс'!$C$10)*N(F$5)*N($A7)
B8: =N('Кіріс'!$C$10)*N(B$5)*N($A8) | C8: =N('Кіріс'!$C$10)*N(C$5)*N($A8) | D8: =N('Кіріс'!$C$10)*N(D$5)*N($A8) | E8: =N('Кіріс'!$C$10)*N(E$5)*N($A8) | F8: =N('Кіріс'!$C$10)*N(F$5)*N($A8)
B9: =N('Кіріс'!$C$10)*N(B$5)*N($A9) | C9: =N('Кіріс'!$C$10)*N(C$5)*N($A9) | D9: =N('Кіріс'!$C$10)*N(D$5)*N($A9) | E9: =N('Кіріс'!$C$10)*N(E$5)*N($A9) | F9: =N('Кіріс'!$C$10)*N(F$5)*N($A9)
B10: =N('Кіріс'!$C$10)*N(B$5)*N($A10) | C10: =N('Кіріс'!$C$10)*N(C$5)*N($A10) | D10: =N('Кіріс'!$C$10)*N(D$5)*N($A10) | E10: =N('Кіріс'!$C$10)*N(E$5)*N($A10) | F10: =N('Кіріс'!$C$10)*N(F$5)*N($A10)
A14: 2) 36-айдағы айлық таза нәтиже (₸): кіріс x (1 - комиссия) - басқа шығындар
A15: Баға (₸/оқушы/жыл) ↓ | Оқушы/мектеп →
B16: =N('Кіріс'!AM10)*N(B$15)*N($A16)/12*(1-N('Болжамдар'!$F$19))-('Шығын'!AM14-'Шығын'!AM13) | C16: =N('Кіріс'!AM10)*N(C$15)*N($A16)/12*(1-N('Болжамдар'!$F$19))-('Шығын'!AM14-'Шығын'!AM13) | D16: =N('Кіріс'!AM10)*N(D$15)*N($A16)/12*(1-N('Болжамдар'!$F$19))-('Шығын'!AM14-'Шығын'!AM13) | E16: =N('Кіріс'!AM10)*N(E$15)*N($A16)/12*(1-N('Болжамдар'!$F$19))-('Шығын'!AM14-'Шығын'!AM13) | F16: =N('Кіріс'!AM10)*N(F$15)*N($A16)/12*(1-N('Болжамдар'!$F$19))-('Шығын'!AM14-'Шығын'!AM13)
B17: =N('Кіріс'!AM10)*N(B$15)*N($A17)/12*(1-N('Болжамдар'!$F$19))-('Шығын'!AM14-'Шығын'!AM13) | C17: =N('Кіріс'!AM10)*N(C$15)*N($A17)/12*(1-N('Болжамдар'!$F$19))-('Шығын'!AM14-'Шығын'!AM13) | D17: =N('Кіріс'!AM10)*N(D$15)*N($A17)/12*(1-N('Болжамдар'!$F$19))-('Шығын'!AM14-'Шығын'!AM13) | E17: =N('Кіріс'!AM10)*N(E$15)*N($A17)/12*(1-N('Болжамдар'!$F$19))-('Шығын'!AM14-'Шығын'!AM13) | F17: =N('Кіріс'!AM10)*N(F$15)*N($A17)/12*(1-N('Болжамдар'!$F$19))-('Шығын'!AM14-'Шығын'!AM13)
B18: =N('Кіріс'!AM10)*N(B$15)*N($A18)/12*(1-N('Болжамдар'!$F$19))-('Шығын'!AM14-'Шығын'!AM13) | C18: =N('Кіріс'!AM10)*N(C$15)*N($A18)/12*(1-N('Болжамдар'!$F$19))-('Шығын'!AM14-'Шығын'!AM13) | D18: =N('Кіріс'!AM10)*N(D$15)*N($A18)/12*(1-N('Болжамдар'!$F$19))-('Шығын'!AM14-'Шығын'!AM13) | E18: =N('Кіріс'!AM10)*N(E$15)*N($A18)/12*(1-N('Болжамдар'!$F$19))-('Шығын'!AM14-'Шығын'!AM13) | F18: =N('Кіріс'!AM10)*N(F$15)*N($A18)/12*(1-N('Болжамдар'!$F$19))-('Шығын'!AM14-'Шығын'!AM13)
B19: =N('Кіріс'!AM10)*N(B$15)*N($A19)/12*(1-N('Болжамдар'!$F$19))-('Шығын'!AM14-'Шығын'!AM13) | C19: =N('Кіріс'!AM10)*N(C$15)*N($A19)/12*(1-N('Болжамдар'!$F$19))-('Шығын'!AM14-'Шығын'!AM13) | D19: =N('Кіріс'!AM10)*N(D$15)*N($A19)/12*(1-N('Болжамдар'!$F$19))-('Шығын'!AM14-'Шығын'!AM13) | E19: =N('Кіріс'!AM10)*N(E$15)*N($A19)/12*(1-N('Болжамдар'!$F$19))-('Шығын'!AM14-'Шығын'!AM13) | F19: =N('Кіріс'!AM10)*N(F$15)*N($A19)/12*(1-N('Болжамдар'!$F$19))-('Шығын'!AM14-'Шығын'!AM13)
B20: =N('Кіріс'!AM10)*N(B$15)*N($A20)/12*(1-N('Болжамдар'!$F$19))-('Шығын'!AM14-'Шығын'!AM13) | C20: =N('Кіріс'!AM10)*N(C$15)*N($A20)/12*(1-N('Болжамдар'!$F$19))-('Шығын'!AM14-'Шығын'!AM13) | D20: =N('Кіріс'!AM10)*N(D$15)*N($A20)/12*(1-N('Болжамдар'!$F$19))-('Шығын'!AM14-'Шығын'!AM13) | E20: =N('Кіріс'!AM10)*N(E$15)*N($A20)/12*(1-N('Болжамдар'!$F$19))-('Шығын'!AM14-'Шығын'!AM13) | F20: =N('Кіріс'!AM10)*N(F$15)*N($A20)/12*(1-N('Болжамдар'!$F$19))-('Шығын'!AM14-'Шығын'!AM13)
A24: Ескерту: ось бос болса кесте 0 немесе тек шығынды көрсетеді. Шығын жағы Болжамдардан келеді.
